<?xml version="1.0" encoding="utf-8"?>
<!-- This URDF was automatically created by SolidWorks to URDF Exporter! Originally created by Stephen Brawner (brawner@gmail.com) 
     Commit Version: 1.6.0-1-g15f4949  Build Version: 1.6.7594.29634
     For more information, please see http://wiki.ros.org/sw_urdf_exporter -->
<robot
  name="1">
  <link
    name="base_link">
    <inertial>
      <origin
        xyz="8.9252E-05 0.040687 0.25548"
        rpy="0 0 0" />
      <mass
        value="3.6348" />
      <inertia
        ixx="0.025881"
        ixy="1.2305E-06"
        ixz="2.0103E-05"
        iyy="0.025906"
        iyz="5.3567E-05"
        izz="0.0024753" />
    </inertial>
    <visual>
      <origin
        xyz="0 0 0"
        rpy="0 0 0" />
      <geometry>
        <mesh
          filename="package://1/meshes/base_link.STL" />
      </geometry>
      <material
        name="">
        <color
          rgba="1 1 1 1" />
      </material>
    </visual>
    <collision>
      <origin
        xyz="0 0 0"
        rpy="0 0 0" />
      <geometry>
        <mesh
          filename="package://1/meshes/base_link.STL" />
      </geometry>
    </collision>
  </link>
  <link
    name="left_wheel_front_Link">
    <inertial>
      <origin
        xyz="0.0097088 -5.4153E-05 0.00073677"
        rpy="0 0 0" />
      <mass
        value="0.82615" />
      <inertia
        ixx="0.0051911"
        ixy="-4.7551E-08"
        ixz="1.0566E-06"
        iyy="0.0028202"
        iyz="1.1756E-07"
        izz="0.0028228" />
    </inertial>
    <visual>
      <origin
        xyz="0 0 0"
        rpy="0 0 0" />
      <geometry>
        <mesh
          filename="package://1/meshes/left_wheel_front_Link.STL" />
      </geometry>
      <material
        name="">
        <color
          rgba="1 1 0.94902 1" />
      </material>
    </visual>
    <collision>
      <origin
        xyz="0 0 0"
        rpy="0 0 0" />
      <geometry>
        <mesh
          filename="package://1/meshes/left_wheel_front_Link.STL" />
      </geometry>
    </collision>
  </link>
  <joint
    name="left_wheel_front_joint"
    type="continuous">
    <origin
      xyz="-0.1039 5.2752E-05 0.085448"
      rpy="0 0 0" />
    <parent
      link="base_link" />
    <child
      link="left_wheel_front_Link" />
    <axis
      xyz="-0.99997 0.00045312 -0.0072447" />
  </joint>
  <link
    name="left_wheel_rear_Link">
    <inertial>
      <origin
        xyz="0.00970884868104751 -4.17620014626927E-05 0.000737576141954854"
        rpy="0 0 0" />
      <mass
        value="0.826148516815797" />
      <inertia
        ixx="0.00519109458017778"
        ixy="-2.97882263924424E-08"
        ixz="1.05727977205832E-06"
        iyy="0.00282022220983345"
        iyz="1.60154685938498E-07"
        izz="0.00282275125627893" />
    </inertial>
    <visual>
      <origin
        xyz="0 0 0"
        rpy="0 0 0" />
      <geometry>
        <mesh
          filename="package://1/meshes/left_wheel_rear_Link.STL" />
      </geometry>
      <material
        name="">
        <color
          rgba="1 1 0.949019607843137 1" />
      </material>
    </visual>
    <collision>
      <origin
        xyz="0 0 0"
        rpy="0 0 0" />
      <geometry>
        <mesh
          filename="package://1/meshes/left_wheel_rear_Link.STL" />
      </geometry>
    </collision>
  </link>
  <joint
    name="left_wheel_rear_joint"
    type="continuous">
    <origin
      xyz="-0.1039 4.0099E-05 0.42145"
      rpy="0 0 0" />
    <parent
      link="base_link" />
    <child
      link="left_wheel_rear_Link" />
    <axis
      xyz="0.99998 0.0024952 0.0060631" />
  </joint>
  <link
    name="right_wheel_front_Link">
    <inertial>
      <origin
        xyz="-0.00970884868027652 3.8073988746899E-05 -0.000737775677446859"
        rpy="0 0 0" />
      <mass
        value="0.826148517222633" />
      <inertia
        ixx="0.00519109458175108"
        ixy="-8.44771274184417E-08"
        ixz="1.05432055405371E-06"
        iyy="0.00282028602396865"
        iyz="-4.27742869112032E-07"
        izz="0.00282268744370533" />
    </inertial>
    <visual>
      <origin
        xyz="0 0 0"
        rpy="0 0 0" />
      <geometry>
        <mesh
          filename="package://1/meshes/right_wheel_front_Link.STL" />
      </geometry>
      <material
        name="">
        <color
          rgba="1 1 0.949019607843137 1" />
      </material>
    </visual>
    <collision>
      <origin
        xyz="0 0 0"
        rpy="0 0 0" />
      <geometry>
        <mesh
          filename="package://1/meshes/right_wheel_front_Link.STL" />
      </geometry>
    </collision>
  </link>
  <joint
    name="right_wheel_front_joint"
    type="continuous">
    <origin
      xyz="0.1039 -4.1409E-05 0.086953"
      rpy="0 0 0" />
    <parent
      link="base_link" />
    <child
      link="right_wheel_front_Link" />
    <axis
      xyz="-0.99997 0.00045312 -0.0072447" />
  </joint>
  <link
    name="right_wheel_rear_Link">
    <inertial>
      <origin
        xyz="-0.00970884868184682 -0.000548819913143516 -0.000494529216344741"
        rpy="0 0 0" />
      <mass
        value="0.826148517020799" />
      <inertia
        ixx="0.0051910877950903"
        ixy="7.64908318413826E-07"
        ixz="7.29516407605811E-07"
        iyy="0.0028213111998838"
        iyz="1.2599618791462E-06"
        izz="0.00282165521175405" />
    </inertial>
    <visual>
      <origin
        xyz="0 0 0"
        rpy="0 0 0" />
      <geometry>
        <mesh
          filename="package://1/meshes/right_wheel_rear_Link.STL" />
      </geometry>
      <material
        name="">
        <color
          rgba="1 1 0.949019607843137 1" />
      </material>
    </visual>
    <collision>
      <origin
        xyz="0 0 0"
        rpy="0 0 0" />
      <geometry>
        <mesh
          filename="package://1/meshes/right_wheel_rear_Link.STL" />
      </geometry>
    </collision>
  </link>
  <joint
    name="right_wheel_rear_joint"
    type="continuous">
    <origin
      xyz="0.1039 0.00055861 0.42271"
      rpy="0 0 0" />
    <parent
      link="base_link" />
    <child
      link="right_wheel_rear_Link" />
    <axis
      xyz="0.99998 0.0024952 0.0060631" />
  </joint>
  <link
    name="base_scan">
    <inertial>
      <origin
        xyz="0 0 0"
        rpy="0 0 0" />
      <mass
        value="0" />
      <inertia
        ixx="0"
        ixy="0"
        ixz="0"
        iyy="0"
        iyz="0"
        izz="0" />
    </inertial>
    <visual>
      <origin
        xyz="0 0 0"
        rpy="0 0 0" />
      <geometry>
        <mesh
          filename="package://1/meshes/base_scan.STL" />
      </geometry>
      <material
        name="">
        <color
          rgba="1 1 1 1" />
      </material>
    </visual>
    <collision>
      <origin
        xyz="0 0 0"
        rpy="0 0 0" />
      <geometry>
        <mesh
          filename="package://1/meshes/base_scan.STL" />
      </geometry>
    </collision>
  </link>
  <joint
    name="base_scan_joint"
    type="fixed">
    <origin
      xyz="-0.000737150267890688 0.186848211076242 0.0757259001306266"
      rpy="0 0 0" />
    <parent
      link="base_link" />
    <child
      link="base_scan" />
    <axis
      xyz="0 0 0" />
  </joint>
</robot>